Workbook

Sheet Test Result
A1: Test Result Summry | S1: TestCase List
A2: Decision Table Case | B2: Total | C2: =COUNTIF(S3:S96,"Decision Table Case") -> 40 | S2: Case Sheet | T2: TCID | U2: Result | V2: Bug List No.
B3: Pass | C3: =COUNTIFS(S:S, "Decision Table Case", U:U, "Pass") -> 31 | S3: Decision Table Case | T3: Login_PO_TC1 | U3: =HLOOKUP(T3,'Decision Table Case'!$D$1:$U$33,33,FALSE) -> Pass
B4: Fail | C4: =COUNTIFS(S:S, "Decision Table Case", U:U, "Fail") -> 9 | S4: Decision Table Case | T4: Login_PO_TC2 | U4: =HLOOKUP(T4,'Decision Table Case'!$D$1:$U$33,33,FALSE) -> Pass
A5: CheckList Case | B5: Total | C5: =COUNTIF(S6:S99,"CheckList Case") -> 24 | S5: Decision Table Case | T5: Login_PO_TC3 | U5: =HLOOKUP(T5,'Decision Table Case'!$D$1:$U$33,33,FALSE) -> Pass
B6: Pass | C6: =COUNTIFS(S:S, "CheckList Case", U:U, "Pass") -> 21 | S6: Decision Table Case | T6: Login_PO_TC4 | U6: =HLOOKUP(T6,'Decision Table Case'!$D$1:$U$33,33,FALSE) -> Pass
B7: Fail | C7: =COUNTIFS(S:S, "CheckList Case", U:U, "Fail") -> 3 | S7: Decision Table Case | T7: Login_PO_TC5 | U7: =HLOOKUP(T7,'Decision Table Case'!$D$1:$U$33,33,FALSE) -> Pass
A8: FieldRule Case | B8: Total | C8: =COUNTIF(S9:S102,"FieldRule Case") -> 29 | S8: Decision Table Case | T8: Login_PO_TC6 | U8: =HLOOKUP(T8,'Decision Table Case'!$D$1:$U$33,33,FALSE) -> Pass
B9: Pass | C9: =COUNTIFS(S:S, "FieldRule Case", U:U, "Pass") -> 24 | S9: Decision Table Case | T9: Login_PO_TC7 | U9: =HLOOKUP(T9,'Decision Table Case'!$D$1:$U$33,33,FALSE) -> Fail
B10: Fail | C10: =COUNTIFS(S:S, "FieldRule Case", U:U, "Fail") -> 5 | S10: Decision Table Case | T10: Login_PO_TC8 | U10: =HLOOKUP(T10,'Decision Table Case'!$D$1:$U$33,33,FALSE) -> Pass
A11: E2E Case | B11: Total | C11: =COUNTIF(S12:S105,"E2E Case") -> 1 | S11: Decision Table Case | T11: Login_PO_TC9 | U11: =HLOOKUP(T11,'Decision Table Case'!$D$1:$U$33,33,FALSE) -> Pass
B12: Pass | C12: =COUNTIFS(S:S, "E2E Case", U:U, "Pass") -> 1 | S12: Decision Table Case | T12: Login_PO_TC10 | U12: =HLOOKUP(T12,'Decision Table Case'!$D$1:$U$33,33,FALSE) -> Pass
B13: Fail | C13: =COUNTIFS(S:S, "E2E Casee", U:U, "Fail") -> 0 | S13: Decision Table Case | T13: Login_PO_TC11 | U13: =HLOOKUP(T13,'Decision Table Case'!$D$1:$U$33,33,FALSE) -> Fail
A14: Total | B14: Total | C14: =SUM(C2,C5,C8,C11) -> 94 | S14: Decision Table Case | T14: Login_PO_TC12 | U14: =HLOOKUP(T14,'Decision Table Case'!$D$1:$U$33,33,FALSE) -> Pass
B15: Pass | C15: =SUM(C3,C6,C9,C12) -> 77 | S15: Decision Table Case | T15: Login_PO_TC13 | U15: =HLOOKUP(T15,'Decision Table Case'!$D$1:$U$33,33,FALSE) -> Pass
B16: Fail | C16: =SUM(C4,C7,C10,C13) -> 17 | S16: Decision Table Case | T16: Login_PO_TC14 | U16: =HLOOKUP(T16,'Decision Table Case'!$D$1:$U$33,33,FALSE) -> Pass
S17: Decision Table Case | T17: Login_PO_TC15 | U17: =HLOOKUP(T17,'Decision Table Case'!$D$1:$U$33,33,FALSE) -> Fail
S18: Decision Table Case | T18: Login_PO_TC16 | U18: =HLOOKUP(T18,'Decision Table Case'!$D$1:$U$33,33,FALSE) -> Pass
S19: Decision Table Case | T19: Login_PO_TC17 | U19: =HLOOKUP(T19,'Decision Table Case'!$D$1:$U$33,33,FALSE) -> Pass
S20: Decision Table Case | T20: Login_PO_TC18 | U20: =HLOOKUP(T20,'Decision Table Case'!$D$1:$U$33,33,FALSE) -> Pass
K21: Test Detail Resilt | S21: Decision Table Case | T21: Login_NE_TC1 | U21: =HLOOKUP(T21,'Decision Table Case'!$D$36:$P$69,34,FALSE) -> Fail | V21: #1
K22: 개수 : Result | L22: 열 레이블 | S22: Decision Table Case | T22: Login_NE_TC2 | U22: =HLOOKUP(T22,'Decision Table Case'!$D$36:$P$69,34,FALSE) -> Pass
K23: 행 레이블 | L23: Fail | M23: Pass | N23: 총합계 | S23: Decision Table Case | T23: Login_NE_TC3 | U23: =HLOOKUP(T23,'Decision Table Case'!$D$36:$P$69,34,FALSE) -> Pass
K24: FieldRule Case | L24: 5 | M24: 24 | N24: 29 | S24: Decision Table Case | T24: Login_NE_TC4 | U24: =HLOOKUP(T24,'Decision Table Case'!$D$36:$P$69,34,FALSE) -> Fail
K25: E2E Case | M25: 1 | N25: 1 | S25: Decision Table Case | T25: Login_NE_TC5 | U25: =HLOOKUP(T25,'Decision Table Case'!$D$36:$P$69,34,FALSE) -> Pass
K26: Decision Table Case | L26: 9 | M26: 31 | N26: 40 | S26: Decision Table Case | T26: Login_NE_TC6 | U26: =HLOOKUP(T26,'Decision Table Case'!$D$36:$P$69,34,FALSE) -> Pass
K27: CheckList Case | L27: 3 | M27: 21 | N27: 24 | S27: Decision Table Case | T27: Login_NE_TC7 | U27: =HLOOKUP(T27,'Decision Table Case'!$D$36:$P$69,34,FALSE) -> Pass
K28: 총합계 | L28: 17 | M28: 77 | N28: 94 | S28: Decision Table Case | T28: Login_NE_TC8 | U28: =HLOOKUP(T28,'Decision Table Case'!$D$36:$P$69,34,FALSE) -> Pass
S29: Decision Table Case | T29: Login_NE_TC9 | U29: =HLOOKUP(T29,'Decision Table Case'!$D$36:$P$69,34,FALSE) -> Pass
S30: Decision Table Case | T30: Login_NE_TC10 | U30: =HLOOKUP(T30,'Decision Table Case'!$D$36:$P$69,34,FALSE) -> Pass
S31: Decision Table Case | T31: Login_NE_TC11 | U31: =HLOOKUP(T31,'Decision Table Case'!$D$36:$P$69,34,FALSE) -> Fail
S32: Decision Table Case | T32: Login_NE_TC12 | U32: =HLOOKUP(T32,'Decision Table Case'!$D$36:$P$69,34,FALSE) -> Pass
S33: Decision Table Case | T33: Login_NE_TC13 | U33: =HLOOKUP(T33,'Decision Table Case'!$D$36:$P$69,34,FALSE) -> Pass
S34: Decision Table Case | T34: Login_Eg_TC1 | U34: =HLOOKUP(T34,'Decision Table Case'!$D$72:$L$95,24,FALSE) -> Pass
S35: Decision Table Case | T35: Login_Eg_TC2 | U35: =HLOOKUP(T35,'Decision Table Case'!$D$72:$L$95,24,FALSE) -> Pass
S36: Decision Table Case | T36: Login_Eg_TC3 | U36: =HLOOKUP(T36,'Decision Table Case'!$D$72:$L$95,24,FALSE) -> Fail
S37: Decision Table Case | T37: Login_Eg_TC4 | U37: =HLOOKUP(T37,'Decision Table Case'!$D$72:$L$95,24,FALSE) -> Pass
S38: Decision Table Case | T38: Login_Eg_TC5 | U38: =HLOOKUP(T38,'Decision Table Case'!$D$72:$L$95,24,FALSE) -> Pass
S39: Decision Table Case | T39: Login_Eg_TC6 | U39: =HLOOKUP(T39,'Decision Table Case'!$D$72:$L$95,24,FALSE) -> Fail
S40: Decision Table Case | T40: Login_Eg_TC7 | U40: =HLOOKUP(T40,'Decision Table Case'!$D$72:$L$95,24,FALSE) -> Pass
...

Sheet Decision Table Case
A1: 로그인 Positive Case | D1: Login_PO_TC1 | E1: Login_PO_TC2 | F1: Login_PO_TC3 | G1: Login_PO_TC4 | H1: Login_PO_TC5 | I1: Login_PO_TC6 | J1: Login_PO_TC7 | K1: Login_PO_TC8 | L1: Login_PO_TC9 | M1: Login_PO_TC10 | N1: Login_PO_TC11 | O1: Login_PO_TC12 | P1: Login_PO_TC13 | Q1: Login_PO_TC14 | R1: Login_PO_TC15 | S1: Login_PO_TC16 | T1: Login_PO_TC17 | U1: Login_PO_TC18
A2: 전제조건① | B2: 실행 브라우저 | C2: Edge | D2: T | G2: T | H2: T | I2: T | J2: T | K2: T | R2: T | U2: T
C3: Chrome | E3: T | L3: T | M3: T | N3: T | O3: T | P3: T | S3: T
C4: Firefox | F4: T | Q4: T | T4: T
A5: 트리거① (진입방법) | B5: 페이지 헤더 로그인 | C5: 버튼 | D5: T | E5: T | T5: T
B6: 예약안내 | C6: 버튼 | F6: T
C7: 메뉴 | G7: T
B8: 질문게시판 | C8: 버튼 | H8: T
C9: 메뉴 | I9: T
B10: 신청내역확인 | C10: 버튼 | J10: T | S10: T
C11: 메뉴 | K11: T
B12: 회사소개 | C12: 버튼 | L12: T
B13: 가격안내 | C13: 버튼 | M13: T
B14: 후기게시판 | C14: 메뉴 | N14: T
B15: 1:1 문의 | C15: 메뉴 | O15: T | U15: T
B16: 회원정보 | C16: 메뉴 | P16: T
B17: URL직접입력 | C17: 하기 URL을 주소창에 입력 http://laundry365.store:8080/LoginInfo/Login | Q17: T | R17: T
A18: 기대결과① | B18: 페이지 타이틀이 "로그인" 일것 | D18: T | E18: T | F18: T | G18: T | H18: T | I18: T | J18: T | K18: T | L18: F | M18: F | N18: T | O18: T | P18: T | Q18: T | R18: T | S18: T | T18: T | U18: T
B19: 페이지 URL이 하기와 같을것 http://laundry365.store:8080/LoginInfo/Login | D19: T | E19: T | F19: T | G19: T | H19: T | I19: T | J19: T | K19: T | N19: T | O19: T | P19: T | Q19: T | R19: T | S19: T | T19: T | U19: T
B20: Layout시트와 동일한 로그인 페이지가 표시될것 | D20: T | E20: T | F20: T | G20: T | H20: T | I20: T | J20: T | K20: T | N20: T | O20: T | P20: T | Q20: T | R20: T | S20: T | T20: T | U20: T
A21: 전재조건② | B21: 일반 유저 | C21: 일반 UserID,Password 입력 | D21: T | F21: T | H21: T | J21: T | N21: T | R21: T | S21: T
B22: 관리자 유저 | C22: 관리자 UserID,Password 입력 | E22: T | G22: T | I22: T | K22: T | O22: T | P22: T | Q22: T | T22: T | U22: T
A23: 트리거② | B23: "Sign in"버튼 클릭 | D23: T | E23: T | F23: T | G23: T | H23: T | I23: T | J23: T | K23: T | N23: T | O23: T | P23: T | Q23: T
B24: "Sign up"버튼 클릭 | R24: T | T24: T
B25: "Password?"버튼 클릭 | S25: T | U25: T
A26: 기대결과② | B26: 로그인에 성공할것 | D26: T | E26: T | F26: T | G26: T | H26: T | I26: T | J26: T | K26: T | N26: T | O26: T | P26: T | Q26: T | R26: F | S26: F | T26: F | U26: F
B27: 페이지 헤더에 "로그인" 메뉴 표시 | D27: F | E27: F | F27: F | G27: F | H27: F | I27: F | J27: F | K27: F | N27: F | O27: F | P27: F | Q27: F | R27: T | S27: T | T27: T | U27: T
B28: 페이지 헤더에 "로그아웃" 메뉴 표시 | D28: T | E28: T | F28: T | G28: T | H28: T | I28: T | J28: T | K28: T | N28: T | O28: T | P28: T | Q28: T | R28: F | S28: F | T28: F | U28: F
B29: 홈페이지로 이동 | C29: 페이지 타이틀이 "Laundry365" 일 것 | D29: T | E29: T | F29: T | G29: T | H29: T | I29: T | J29: T | K29: T | N29: T | O29: T | P29: T | Q29: T
C30: 페이지 URL이 하기와 같을것 http://laundry365.store:8080/ | D30: T | E30: T | F30: T | G30: T | H30: T | I30: T | J30: T | K30: T | N30: T | O30: T | P30: T | Q30: T
B31: 회원가입 페이지로이동 | R31: T | T31: T
B32: 비밀번호 찾기 페이지로 이동 | S32: T | U32: T
A33: 실행결과 (Pass/Fail) | D33: Pass | E33: Pass | F33: Pass | G33: Pass | H33: Pass | I33: Pass | J33: Fail | K33: Pass | L33: Pass | M33: Pass | N33: Fail | O33: Pass | P33: Pass | Q33: Pass | R33: Fail | S33: Pass | T33: Pass | U33: Pass
A36: 로그인 Negative Case (로그인 실패) | D36: Login_NE_TC1 | E36: Login_NE_TC2 | F36: Login_NE_TC3 | G36: Login_NE_TC4 | H36: Login_NE_TC5 | I36: Login_NE_TC6 | J36: Login_NE_TC7 | K36: Login_NE_TC8 | L36: Login_NE_TC9 | M36: Login_NE_TC10 | N36: Login_NE_TC11 | O36: Login_NE_TC12 | P36: Login_NE_TC13
A37: 전제조건① | B37: 실행 브라우저 | C37: Edge | D37: T | I37: T | M37: T | N37: T
C38: Chrome | E38: T | G38: T | H38: T | J38: T | K38: T | L38: T | P38: T
C39: Firefox | F39: T | O39: T
A40: 트리거① (진입방법) | B40: 페이지 헤더 로그인 | C40: 버튼 | D40: T | E40: T
B41: 예약안내 | C41: 버튼 | F41: T
C42: 메뉴 | G42: T
...

Sheet CheckList Case
A1: 결제관련 CheckList Case
A2: No | B2: 대분류 | C2: TCID | D2: 우선순위 | E2: 사전조건 | F2: 테스트 절차 | G2: 기대결과 | H2: 실행결과 (Pass/Fail) | I2: 비고
A3: 1 | B3: UI/필드 | C3: Payment_UI_TC1 | D3: Medium | E3: 주문 생성 후 결제 페이지 진입 | F3: 결제수단 선택 영역(카드결제) UI 표시 여부 확인 | G3: 결제수단 선택 라디오버튼/드롭다운이 정상적으로 표시될 것 | H3: Pass
A4: 2 | B4: UI/필드 | C4: Payment_UI_TC2 | D4: Low | E4: 결제 페이지 진입 | F4: 결제 예정 금액 표시 형식 확인 | G4: 천단위 콤마 및 원화기호(₩)가 포함되어 정상 표시될 것 | H4: Pass
A5: 3 | B5: UI/필드 | C5: Payment_UI_TC3 | D5: Medium | E5: 결제 페이지 진입, 결제수단 미선택 상태 | F5: 결제하기 버튼 클릭 가능 여부 확인 | G5: 결제수단 미선택 시 '결제하기' 버튼이 비활성화(disabled) 상태일 것 | H5: Pass
A6: 4 | B6: Positive | C6: Payment_PO_TC1 | D6: High | E6: 테스트 고객 계정(kim9502072) 로그인, 주문 생성 완료 | F6: Iamport 테스트 모드 카드정보로 결제 진행 → 결제하기 클릭 | G6: 결제가 정상적으로 완료되고 완료 안내 화면으로 이동할 것 | H6: Pass
A7: 5 | B7: Positive | C7: Payment_PO_TC2 | D7: High | E7: Payment_PO_TC1 결제 완료 상태 | F7: 마이페이지 > 주문내역 조회 | G7: 해당 주문의 상태가 '결제완료'로 변경되어 있을 것 | H7: Pass
A8: 6 | B8: Positive | C8: Payment_PO_TC3 | D8: Medium | E8: Payment_PO_TC1 결제 완료 상태 | F8: 마이페이지 > 주문상세 조회 | G8: 결제금액이 실제 주문금액과 동일하게 표시될 것 | H8: Pass
A9: 7 | B9: Positive | C9: Payment_PO_TC4 | D9: Low | E9: Payment_PO_TC1 결제 완료 상태 | F9: 결제 완료 직후 화면 확인 | G9: 결제 완료 안내 메시지 또는 영수증 정보가 표시될 것 | H9: Pass
A10: 8 | B10: Negative | C10: Payment_NE_TC1 | D10: High | E10: 결제 페이지 진입, 결제수단 미선택 | F10: 필수 결제정보 미입력 상태로 '결제하기' 클릭 시도 | G10: 결제가 진행되지 않고 안내 메시지가 표시될 것(버튼 비활성화 또는 Alert) | H10: Pass
A11: 9 | B11: Negative | C11: Payment_NE_TC2 | D11: Medium | E11: 결제 페이지 진입 | F11: Iamport 테스트 모드 내 유효기간 만료 카드정보 입력 후 결제 시도 | G11: 결제 실패 처리되며 실패 사유 Alert가 표시될 것 | H11: Pass
A12: 10 | B12: Negative | C12: Payment_NE_TC3 | D12: Medium | E12: 결제 페이지 진입 | F12: Iamport 테스트 모드 내 잔액부족 테스트카드로 결제 시도 | G12: 결제 실패 처리되며 '잔액부족' 관련 Alert가 표시될 것 | H12: Pass
A13: 11 | B13: Negative | C13: Payment_NE_TC4 | D13: Medium | E13: 결제창(Iamport 팝업) 오픈 상태 | F13: 결제창 내 '취소' 버튼 클릭 | G13: 결제창이 종료되고 주문이 '결제대기' 또는 미생성 상태로 유지될 것(결제완료 처리되지 않음) | H13: Pass
A14: 12 | B14: 보안/핵심검증 | C14: Payment_Sec_TC1 | D14: Critical | E14: 주문 생성 완료, 개발자도구로 요청 조작 가능한 환경 | F14: 클라이언트 결제요청 시 금액 파라미터를 실제 주문금액보다 낮게 변조하여 전송 | G14: 서버가 상품 원가와 클라이언트 전달 금액을 비교 검증하여 변조된 결제 요청을 거부할 것 | H14: Pass | I14: 최우선 검증 필요(금액 위변조 방지)
A15: 13 | B15: 보안/핵심검증 | C15: Payment_Sec_TC2 | D15: Critical | E15: 결제 콜백 수신 가능한 환경(imp_uid 확보) | F15: 결제 완료 콜백에서 전달된 imp_uid를 서버가 Iamport 서버 API로 재조회하여 실결제 여부를 검증하는지 확인 | G15: 서버가 클라이언트 콜백을 그대로 신뢰하지 않고, Iamport API를 통해 imp_uid의 실제 결제 상태/금액을 재검증할 것 | H15: Fail | I15: 서버가 Iamport API를 호출하지 않고 클라이언트 콜백만으로 결제완료 처리함
A16: 14 | B16: 보안/핵심검증 | C16: Payment_Sec_TC3 | D16: High | E16: 이미 결제 완료된 imp_uid 보유 | F16: 동일 imp_uid로 결제완료 요청을 중복 전송 | G16: 중복 주문/중복 결제완료 처리가 발생하지 않고 서버에서 차단할 것 | H16: Pass
A17: 15 | B17: 보안/핵심검증 | C17: Payment_Sec_TC4 | D17: High | E17: 결제 미완료(결제대기) 주문 1건 보유 | F17: 해당 주문의 상세페이지 URL을 주소창에 직접 입력하여 접근 | G17: 결제 미완료 상태 그대로 노출되며 '결제완료'로 오인 표시되지 않을 것 | H17: Pass
A18: 16 | B18: Edge | C18: Payment_Eg_TC1 | D18: Medium | E18: 결제창(Iamport 팝업) 진행 중 | F18: 카드정보 입력 후 결제 처리 중 네트워크 연결 해제 | G18: 타임아웃 또는 네트워크 오류 안내 메시지가 표시되고, 중복결제로 이어지지 않을 것 | H18: Pass
A19: 17 | B19: Edge | C19: Payment_Eg_TC2 | D19: Medium | E19: 결제창(Iamport 팝업) 오픈 상태 | F19: 결제창을 완료/취소 없이 강제로 닫기(X버튼 또는 브라우저 종료) | G19: 주문이 결제완료 상태로 전환되지 않고 '결제대기' 상태로 유지될 것 | H19: Pass
A20: 18 | B20: Edge | C20: Payment_Eg_TC3 | D20: High | E20: 결제 처리 중(서버 응답 대기 상태) | F20: 결제 요청 전송 직후 새로고침(F5) 실행 | G20: 동일 주문에 대해 중복 결제(재요청)가 발생하지 않을 것 | H20: Pass
A21: 19 | B21: Edge | C21: Payment_Eg_TC4 | D21: High | E21: 주문 생성 화면 진입 | F21: 세탁 서비스 수량 입력란에 비정상적으로 큰 값(예: 99999) 입력 후 결제 진행 | G21: 서버 측에서 수량 유효성 검증을 통해 비정상 주문 생성을 차단할 것 | H21: Fail | I21: 서버 측 수량 유효성 검증 로직 부재로 비정상 수량 그대로 주문 생성됨
A22: 20 | B22: Edge | C22: Payment_Eg_TC5 | D22: High | E22: 예약 화면 진입 | F22: 예약일자를 오늘 이전 과거 날짜로 선택 후 결제 진행 | G22: 서버 측에서 과거 날짜 예약을 차단할 것 | H22: Fail | I22: 서버 측 날짜 유효성 검증 로직 부재로 과거 날짜 예약이 결제까지 정상 진행
A23: 21 | B23: 환불 | C23: Payment_Refund_TC1 | D23: High | E23: 결제완료 주문 1건 보유 | F23: 마이페이지 > 주문내역 > 환불 요청 버튼 클릭 → 사유 입력 후 제출 | G23: 환불 요청이 정상 접수되고 주문 상태가 '환불요청'으로 변경될 것 | H23: Pass
A24: 22 | B24: 환불 | C24: Payment_Refund_TC2 | D24: Medium | E24: 환불 처리 완료된 주문 1건 보유 | F24: 이미 환불 완료된 주문에 대해 재차 환불 요청 시도 | G24: 이미 처리된 건임을 안내하며 재요청이 차단될 것 | H24: Pass
A25: 23 | B25: 환불 | C25: Payment_Refund_TC3 | D25: Low | E25: 환불 요청 접수 상태 | F25: 마이페이지 주문상세 조회 | G25: 주문 상태가 '환불처리중'으로 정상 반영되어 표시될 것 | H25: Pass
A26: 24 | B26: 환불 | C26: Payment_Refund_TC4 | D26: Critical | E26: 타 사용자 소유 주문의 orderId 확보 | F26: 본인 계정으로 로그인한 상태에서 타 사용자 주문의 환불 요청 URL(orderId 직접 조작)로 접근 | G26: 권한 없음 처리되어 환불 요청이 차단될 것(타인 주문 환불 불가) | H26: Pass

Sheet FieldRule Case
A1: 로그인 페이지 FieldRule Case
A2: No | B2: TCID | C2: 필드ID | D2: 종류 | E2: 확인대상 | F2: 확인내용 | G2: 입력값 | H2: 기대값 | I2: 실행결과 (Pass/Fail) | K2: Style Guide
A3: 1 | B3: Login_FieldID1_TC1 | C3: 1 | D3: Text | E3: Text | F3: "User Login" 표시확인 | H3: User Login | I3: Pass
A4: 2 | B4: Login_FieldID2_TC1 | C4: 2 | D4: Inputbox | E4: Inputbox | F4: User id를 입력할 수 있는 inputbox 표시되는 것을 확인 | I4: Pass
A5: 3 | B5: Login_FieldID2_TC2 | E5: 동작여부 | F5: 클릭시 입력 가능여부 확인 | I5: Pass
A6: 4 | B6: Login_FieldID2_TC3 | E6: 입력유효성 | F6: 최대값(영문+숫자 15자) 입력 가능여부 확인 | G6: TestUser0123456 | H6: TestUser012345 | I6: Fail
A7: 5 | B7: Login_FieldID2_TC4 | E7: 입력유효성 | F7: 특수문자 입력불가 여부 확인 | G7: 임의특수문자(!,*,@,★ 등) | H7: 입력되지 않음 | I7: Pass
A8: 6 | B8: Login_FieldID3_TC1 | C8: 3 | D8: Inputbox | E8: Inputbox | F8: Password를 입력할 수 있는 inputbox 표시되는 것을 확인 | I8: Pass
A9: 7 | B9: Login_FieldID3_TC2 | E9: 동작여부 | F9: 클릭시 입력 가능여부 확인 | I9: Pass
A10: 8 | B10: Login_FieldID3_TC3 | E10: 입력유효성 | F10: 최대값(20자) 입력 가능여부 확인 ※로그인 버튼클릭후, LoginPost의 페이로드의 pwd가 기대값이 되어있는것을 확인 | G10: TestUser01234!@#abcd1 | H10: TestUser01234!@#abcd | I10: Fail
A11: 9 | B11: Login_FieldID3_TC4 | E11: 마스킹 | F11: 입력한 비밀번호가 로그인 페이지에서 마스킹처리 되는것을 확인 ※로그인 버튼클릭후, LoginPost의 페이로드의 pwd가 입력값과 동일한 것을 확인 | G11: abc1234 | H11: ●●●●●●● | I11: Pass
A12: 10 | B12: Login_FieldID3_TC5 | E12: 추가동작 | F12: 해당 필드 클릭후, CapsLock을 켜서 필드하부에 메시지가 표시되는것을 확인 ※CapsLock을 끄면 해당메세지가 삭제되는것을 확인 | G12: CapsLock On/Off | H12: "Caps Lock이 켜져 있습니다." | I12: Fail
A13: 11 | B13: Login_FieldID4_TC1 | C13: 4 | D13: Button | E13: Text | F13: "Sign in" 표시확인 | H13: Sign in | I13: Pass
A14: 12 | B14: Login_FieldID4_TC2 | E14: 동작여부 | F14: 클릭 가능한것을 확인 | I14: Pass
A15: 13 | B15: Login_FieldID4_TC3 | E15: UI | F15: 버튼색 : 블랙 | I15: Pass
A16: 14 | B16: Login_FieldID4_TC4 | E16: UI | F16: 텍스트색 : 화이트 | I16: Pass
A17: 15 | B17: Login_FieldID4_TC5 | E17: UI | F17: 마우스를 버튼에 올리면 버튼색의 투명도 상승 | I17: Fail
A18: 16 | B18: Login_FieldID5_TC1 | C18: 5 | D18: Button | E18: Text | F18: "Sign up" 표시확인 | H18: Sign up | I18: Pass
A19: 17 | B19: Login_FieldID5_TC2 | E19: 동작여부 | F19: 클릭 가능한것을 확인 | I19: Pass
A20: 18 | B20: Login_FieldID5_TC3 | E20: UI | F20: 버튼색 : 화이트 | I20: Pass
A21: 19 | B21: Login_FieldID5_TC4 | E21: UI | F21: 텍스트색 : 블랙 | I21: Pass
A22: 20 | B22: Login_FieldID5_TC5 | E22: UI | F22: 마우스를 버튼에 올리면 버튼색이 블랙으로 변경 | I22: Pass
A23: 21 | B23: Login_FieldID6_TC1 | C23: 6 | D23: Button | E23: Text | F23: "Password" 표시확인 | H23: Password | I23: Pass
A24: 22 | B24: Login_FieldID6_TC2 | E24: 동작여부 | F24: 클릭 가능한것을 확인 | I24: Pass
A25: 23 | B25: Login_FieldID6_TC3 | E25: UI | F25: 버튼색 : 화이트 | I25: Pass
A26: 24 | B26: Login_FieldID6_TC4 | E26: UI | F26: 텍스트색 : 블랙 | I26: Pass
A27: 25 | B27: Login_FieldID6_TC5 | E27: UI | F27: 마우스를 버튼에 올리면 버튼색이 블랙으로 변경 | I27: Fail
A28: 26 | B28: Login_FieldID7_TC1 | C28: 7 | D28: Header | E28: 텍스트 | F28: 네비게이션의 텍스트들이 올바르게 표시되어 있는것을 확인 | I28: Pass
A29: 27 | B29: Login_FieldID7_TC2 | E29: UI | F29: 네비게이션의 UI깨짐 현상이 없을것 | I29: Pass
A30: 28 | B30: Login_FieldID8_TC1 | C30: 8 | D30: Footer | E30: 텍스트 | F30: 푸터의 텍스트들이 올바르게 표시되어 있는것을 확인 | I30: Pass
A31: 29 | B31: Login_FieldID8_TC2 | E31: UI | F31: 푸터의 UI깨짐 현상이 없을것 | I31: Pass

Sheet E2E Case
A1: 주문관련 E2E Case
A2: 시나리오ID | B2: E2E_Order_Critical_01 | D2: 실행결과(Pass/Fail)
A3: 시나리오 요약 | B3: 신규회원의 복수상품 예약 및 결제와 금액변조 차단확인, 관리자의 상태 변경 통합 검증 | D3: Pass
A4: 테스트 목적 | B4: 신규 유입 사용자의 핵심 시나리오인 '로그인 - 예약 - 결제'에 이르는 전체 비즈니스 로직 검증
A5: 사전 조건 | B5: 1. 테스트용 신규 계정(test_user_01) 작성 및 활성화 상태 2. 결제는 테스트 환경에서의 결제진행
A7: Step | B7: Action | C7: 기대결과1 | D7: 기대결과2 | E7: 기대결과3 | F7: 비고
A8: 1 | B8: 로그인페이지에서 test_user_01로 로그인 | C8: 홈페이지로 이동 | D8: 이동한 홈페이지의 URL이 하기와 동일할 것 http://laundry365.store:8080/
A9: 2 | B9: 홈페이지에서 네비게이션 바의 예약안내 버튼 클릭 | C9: 예약안내 페이지로 이동 | D9: 4개의 카테고리 표시 및 선택가능할 것
A10: 3 | B10: 생활빨래 카테고리선택 | C10: 상품선택 페이지로 이동 | D10: 이동한 홈페이지의 URL이 하기와 동일할 것 http://laundry365.store:8080/Reserve/Select?category=clothes | E10: 상품명이 "생활빨래" 로 표시
A11: 4 | B11: 옵션에서 임의의 복수 상품선택 후 수량 변경 | C11: 각각의 상품 가격이 올바르게 표시 | D11: 총 상품 금액이 올바르게 표시 | E11: 예약하기 버튼 활성화 | F11: 상품가격 : PriceGuideData.xlsx 참조
A12: 5 | B12: 예약날짜 설정 후 예약하기 버튼 클릭 ※개발자도구 네트워크탭 활성화 | C12: 결제 페이지로 이동 | D12: 상품, 수량, 총 주문가격, 수거날짜가 선택/입력한 내용과 일치 할 것 | E12: [API] GET /Reserve/Payment 호출 시, 페이로드의 name, price, count, date, category가 선택 값대로 정확히 전달 된 것을 확인
A13: 6 | B13: URL 파라미터 중 price 값을 임의의 낮은 금액으로 변경 후 엔터키로 이동 (예시 : 가격%2F4000%2F5000 → 가격%2F40%2F50) | C13: Alert메세지 표시 - 타이틀 : Error - 메시지 : "잘못된 접근입니다." - 버튼 : "확인" | F13: ※해당 케이스는 파라미터 변조를 통한 결제 금액 위변조 가능성을 확인하기 위함
A14: 7 | B14: Alert메세지의 확인버튼 클릭 | C14: 결제 페이지로 이동 ※Step5의 기대결과와 동일 | D14: 상품, 수량, 총 주문가격, 수거날짜가 선택/입력한 내용과 일치 할 것 ※Step5의 기대결과와 동일 | E14: [API] GET /Reserve/Payment 호출 시, 페이로드의 name, price, count, date, category가 선택 값대로 정확히 전달 된 것을 확인 ※Step5의 기대결과와 동일
A15: 8 | B15: 요청사항, 결제 정보 이메일 입력후 카드결제 버튼클릭 | C15: KG이니시스 결제화면 표시 | D15: 상품명, 상품가격, 결재금액이 올바른 값일 것
A16: 9 | B16: 테스트카드로 결제완료 | C16: Alert메세지 표시 - 타이틀 : 결제완료 - 메시지 : "결제가 완료되었습니다." - 버튼 : "확인"
A17: 10 | B17: Alert메세지의 확인버튼 클릭 | C17: 신청내역확인 페이지로 이동 | D17: 이동한 홈페이지의 URL이 하기를 포함할 것 http://laundry365.store:8080/LoginInfo/Mypage/OrderList?pageNum=1 | E17: 결제완료한 주문이 표시되는 것을 확인 | F17: ※주문번호를 확인/메모
A18: 11 | B18: 해당 주문에 대한 상세보기 버튼클릭 | C18: 주문상세 페이지로 이동 | D18: 주문정보 및 주문내용이 올바른 값일 것 | F18: ※로그아웃
A19: 12 | B19: [관리자] test_adminuser_01로 로그인하여 주문관리 버튼클릭 | C19: 주문관리 페이지로 이동 | D19: 이동한 홈페이지의 URL이 하기와 동일할 것 http://laundry365.store:8080/LoginInfo/Mypage/OrderList
A20: 13 | B20: [관리자] 주문번호 검색 후, 수거용 송장번호 발급 버튼클릭 | C20: 해당주문의 상태 "결제완료"일 것 | D20: 주문관리 페이지에서 해당 주문의 수거용 송장번호 표시 | E20: 주문상세 페이지에서 해당 주문의 수거용 송장번호 표시
A21: 14 | B21: [관리자] 주문상태를 "세탁완료"로 변경 후, 반환용 송장번호 발급 버튼클릭 | C21: 해당주문의 상태 "세탁완료"일 것 | D21: 주문관리 페이지에서 해당 주문의 반환용 송장번호 표시 | E21: 주문상세 페이지에서 해당 주문의 반환용 송장번호 표시
A22: 15 | B22: [관리자] 주문상태를 "반환완료"로 변경 | C22: 해당주문의 상태 "반환완료"일 것 | D22: 주문관리 페이지에서 해당 주문의 수거/반환용 송장번호 표시 | E22: 주문상세 페이지에서 해당 주문의 수거/반환용 송장번호 표시 | F22: ※송장번호를 확인/메모 및 로그아웃
A23: 16 | B23: [사용자] 신청내역확인 페이지 이동 | C23: 신청내역확인 페이지에서 해당 주문의 수거/반환용 송장번호 표시 ※Step15에서 확인한 송장번호와 동일할 것 | D23: 처리상태가 "반환완료" 로 표시 | E23: 후기작성이 "작성하기"로 표시 및 활성화 상태
A24: 17 | B24: [사용자] 해당 주문의 주문상세 페이지 이동 | C24: 주문상세 페이지에서 해당 주문의 수거/반환용 송장번호 표시 ※Step15에서 확인한 송장번호와 동일할 것 | D24: 주문상태가 "반환완료" 로 표시

Sheet Bug Report
A1: Bug Report
A3: Bug List No. | B3: #1
A4: 제목 | B4: [로그인페이지]로그인 실패시 Alert메세지 비표시
A5: 테스트케이스 | B5: Login_NE_TC1
A6: 페이지 / 기능 | B6: 로그인 페이지
A7: 결함 심각도 | B7: Major
A8: 테스트환경 | B8: Chrome
A9: 재현경로 | B9: 1. Chrome브라우저로 홈페이지 진입 2. 페이지헤더(네비게이션바)의 로그인메뉴 클릭 3. 일반유저의 UserID입력 4. 잘못된 Password 입력 5. "Sign in"버튼 클릭
A10: 기대결과 | B10: 로그인에 실패하여 아래와 같은 Alert메세지가 표시될 것 - 타이틀 : "로그인 실패" - 메시지 : "아이디와 비밀번호를 입력해주세요." - 버튼 : "확인"
A11: 실제결과 | B11: 로그인에 실패하였으나 Alert메세지가 표시되지 않음
A12: 재현영상 파일명 | B12: Login_NE_TC1.mp4
A13: 비고
A15: Bug List No. | B15: #2
A16: 제목 | B16: [예약/결제]예약일 과거일자 설정에도 정상결제 처리되는 현상
A17: 테스트케이스 | B17: Payment_Eg_TC5
A18: 페이지 / 기능 | B18: 예약페이지, 결제페이지
A19: 결함 심각도 | B19: Major
A20: 테스트환경 | B20: Chrome
A21: 재현경로 | B21: 1. Chrome브라우저로 홈페이지 진입 2. 일반유저로 로그인 3. 예약 화면 진입 4. 임의의 카테고리 선택 5. 예약날짜를 과거로 선택 6. 임의의 옵션선택 후, 예약하기 버튼 클릭 7. 결제진행 (카드결제 : 테스트 토스카드로 결제진행)
A22: 기대결과 | B22: 예약일자를 오늘 이전 과거 날짜로 선택 후 결제 진행시, 서버 측에서 과거 날짜 예약을 차단
A23: 실제결과 | B23: 서버 측에서 과거 날짜 예약을 차단되지 않고, 정상결제 처리
A24: 재현영상 파일명 | B24: Payment_Eg_TC5.mp4
A25: 비고 | B25: 서버 측 날짜 유효성 검증 로직 부재로 과거 날짜 예약이 결제까지 정상 진행
A27: Bug List No. | B27: #3
... A36: 재현영상 파일명 | B36: Login_FieldID3_TC5.mp4
A37: 비고

Sheet Layout
